<?xml version="1.0"?>
<robot name="basic_robot">

  <!-- 定义机器人主体的链接 -->
  <link name="base_link">
    <visual>
      <geometry>
        <box size="0.5 0.5 0.5" />
      </geometry>
      <material name="blue">
        <color rgba="0 0 1 1" />
      </material>
    </visual>
    <collision>
      <geometry>
        <box size="0.5 0.5 0.5" />
      </geometry>
    </collision>
  </link>

  <!-- 定义一个关节，连接base_link到一个新的链接 -->
  <joint name="base_to_arm" type="revolute">
    <parent link="base_link" />
    <child link="arm_link" />
    <origin xyz="0 0 0.5" rpy="0 0 0" />
    <axis xyz="0 0 1" />
    <limit lower="0" upper="1.57" effort="10" velocity="1" />
  </joint>

  <!-- 定义arm_link链接 -->
  <link name="arm_link">
    <visual>
      <geometry>
        <cylinder radius="0.05" length="0.5" />
      </geometry>
      <material name="green">
        <color rgba="0 1 0 1" />
      </material>
    </visual>
    <collision>
      <geometry>
        <cylinder radius="0.05" length="0.5" />
      </geometry>
    </collision>
  </link>

</robot>
